Workbook

Sheet Form Responses 1
A1: Timestamp | B1: Username | C1: LC R3 [Peterborough vs Barnsley] | D1: LC R3 [West Ham vs Fulham] | E1: LC R3 [Ipswich vs Arsenal] | F1: LC R3 [Liverpool vs Spurs] | G1: LC R3 [Reading vs Brentford] | H1: LC R3 [Everton vs Wolves] | I1: LC R3 [Fleetwood vs Sheffield Utd] | J1: LC R3 [Coventry vs Aston Villa] | K1: LC R3 [Man Utd vs Brighton] | L1: LC R3 [Man City vs Norwich] | P1: Away | Q1: Draw | R1: Away | S1: Draw | T1: Draw | U1: Draw | V1: Away | W1: Away | X1: Away | Y1: Home
A2: 46254.626 | B2: MadeMIGMIG | C2: Home | D2: Away | E2: Away | F2: Draw | G2: Away | H2: Away | I2: Away | J2: Home | K2: Away | L2: Draw | N2: MadeMIGMIG | O2: 3 | P2: 1 | Q2: 0 | R2: 0 | S2: 0 | T2: 1 | U2: 0 | V2: 0 | W2: 1 | X2: 0 | Y2: 0 | AA2: PL MD1 | AB2: Arsenal 3 - 0 Coventry | AC2: Hull 2 - 0 Man Utd | AD2: Everton 2 - 0 Crystal Palace | AE2: Ipswich 2 - 1 Sunderland | AF2: Nott'm Forest 0 - 1 Leeds | AG2: Brentford 3 - 0 Spurs | AH2: Brighton 4 - 0 Aston Villa | AI2: Man City 2 - 1 Bournemouth | AJ2: Newcastle 2 - 2 Liverpool | AK2: Fulham 2 - 3 Chelsea
A3: 46254.628 | B3: AffectionateLeg9895 | C3: Home | D3: Away | E3: Draw | F3: Draw | G3: Draw | H3: Draw | I3: Draw | J3: Home | K3: Away | L3: Away | N3: AffectionateLeg9895 | O3: 3 | P3: 1 | Q3: 0 | R3: 0 | S3: 0 | T3: 0 | U3: 0 | V3: 0 | W3: 1 | X3: 0 | Y3: 1 | AA3: H | AB3: 45 | AC3: 0 | AD3: 15 | AE3: 2 | AF3: 20 | AG3: 9 | AH3: 18 | AI3: 41 | AJ3: 2 | AK3: 3
A4: 46254.628 | B4: m_audette99 | C4: Draw | D4: Away | E4: Draw | F4: Draw | G4: Away | H4: Home | I4: Away | J4: Home | K4: Away | L4: Away | N4: m_audette99 | O4: 4 | P4: 0 | Q4: 0 | R4: 0 | S4: 0 | T4: 1 | U4: 1 | V4: 0 | W4: 1 | X4: 0 | Y4: 1 | AA4: D | AB4: 3 | AC4: 5 | AD4: 34 | AE4: 15 | AF4: 18 | AG4: 19 | AH4: 21 | AI4: 13 | AJ4: 10 | AK4: 11
A5: 46254.631 | B5: asparagusdreaming | C5: Home | D5: Draw | E5: Home | F5: Draw | G5: Home | H5: Away | I5: Draw | J5: Draw | K5: Away | L5: Draw | N5: asparagusdreaming | O5: 2 | P5: 1 | Q5: 0 | R5: 1 | S5: 0 | T5: 0 | U5: 0 | V5: 0 | W5: 0 | X5: 0 | Y5: 0 | AA5: A | AB5: 2 | AC5: 47 | AD5: 4 | AE5: 36 | AF5: 15 | AG5: 25 | AH5: 16 | AI5: 1 | AJ5: 43 | AK5: 41
A6: 46254.631 | B6: 26ld | C6: Home | D6: Draw | E6: Home | F6: Draw | G6: Draw | H6: Home | I6: Home | J6: Draw | K6: Draw | L6: Draw | N6: 26ld | O6: 5 | P6: 1 | Q6: 0 | R6: 1 | S6: 0 | T6: 0 | U6: 1 | V6: 1 | W6: 0 | X6: 1 | Y6: 0
A7: 46254.632 | B7: Ummagumma- | C7: Home | D7: Away | E7: Draw | F7: Away | G7: Home | H7: Away | I7: Draw | J7: Home | K7: Home | L7: Away | N7: Ummagumma- | O7: 3 | P7: 1 | Q7: 0 | R7: 0 | S7: 0 | T7: 0 | U7: 0 | V7: 0 | W7: 1 | X7: 0 | Y7: 1
A8: 46254.636 | B8: Dudhjalebi | C8: Home | D8: Away | E8: Draw | F8: Away | G8: Home | H8: Draw | I8: Away | J8: Home | K8: Away | L8: Away | N8: Dudhjalebi | O8: 3 | P8: 1 | Q8: 0 | R8: 0 | S8: 0 | T8: 0 | U8: 0 | V8: 0 | W8: 1 | X8: 0 | Y8: 1
A9: 46254.638 | B9: chopke | C9: Home | D9: Away | E9: Home | F9: Away | G9: Home | H9: Away | I9: Draw | J9: Home | K9: Away | L9: Away | N9: chopke | O9: 4 | P9: 1 | Q9: 0 | R9: 1 | S9: 0 | T9: 0 | U9: 0 | V9: 0 | W9: 1 | X9: 0 | Y9: 1
A10: 46254.639 | B10: prestidigigreen | C10: Home | D10: Away | E10: Draw | F10: Draw | G10: Home | H10: Away | I10: Home | J10: Home | K10: Away | L10: Away | N10: prestidigigreen | O10: 4 | P10: 1 | Q10: 0 | R10: 0 | S10: 0 | T10: 0 | U10: 0 | V10: 1 | W10: 1 | X10: 0 | Y10: 1
A11: 46254.641 | B11: JhnCook | C11: Home | D11: Away | E11: Home | F11: Away | G11: Draw | H11: Draw | I11: Home | J11: Home | K11: Away | L11: Away | N11: JhnCook | O11: 5 | P11: 1 | Q11: 0 | R11: 1 | S11: 0 | T11: 0 | U11: 0 | V11: 1 | W11: 1 | X11: 0 | Y11: 1
A12: 46254.644 | B12: narwoolTF2 | C12: Home | D12: Draw | E12: Away | F12: Away | G12: Draw | H12: Home | I12: Away | J12: Home | K12: Away | L12: Away | N12: narwoolTF2 | O12: 4 | P12: 1 | Q12: 0 | R12: 0 | S12: 0 | T12: 0 | U12: 1 | V12: 0 | W12: 1 | X12: 0 | Y12: 1
A13: 46254.645 | B13: zigooloo | C13: Home | D13: Away | E13: Draw | F13: Draw | G13: Away | H13: Away | I13: Home | J13: Home | K13: Draw | L13: Away | N13: zigooloo | O13: 6 | P13: 1 | Q13: 0 | R13: 0 | S13: 0 | T13: 1 | U13: 0 | V13: 1 | W13: 1 | X13: 1 | Y13: 1
A14: 46254.649 | B14: sjrotella | C14: Home | D14: Away | E14: Draw | F14: Away | G14: Away | H14: Draw | I14: Draw | J14: Draw | K14: Away | L14: Draw | N14: sjrotella | O14: 2 | P14: 1 | Q14: 0 | R14: 0 | S14: 0 | T14: 1 | U14: 0 | V14: 0 | W14: 0 | X14: 0 | Y14: 0
A15: 46254.653 | B15: Ninovd | C15: Home | D15: Away | E15: Draw | F15: Away | G15: Draw | H15: Away | I15: Away | J15: Away | K15: Draw | L15: Away | N15: Ninovd | O15: 3 | P15: 1 | Q15: 0 | R15: 0 | S15: 0 | T15: 0 | U15: 0 | V15: 0 | W15: 0 | X15: 1 | Y15: 1
A16: 46254.653 | B16: ASGT908 | C16: Home | D16: Away | E16: Draw | F16: Away | G16: Draw | H16: Away | I16: Draw | J16: Home | K16: Away | L16: Away | N16: ASGT908 | O16: 3 | P16: 1 | Q16: 0 | R16: 0 | S16: 0 | T16: 0 | U16: 0 | V16: 0 | W16: 1 | X16: 0 | Y16: 1
A17: 46254.656 | B17: mystic_wang_force | C17: Home | D17: Away | E17: Draw | F17: Away | G17: Draw | H17: Home | I17: Draw | J17: Home | K17: Draw | L17: Away | N17: mystic_wang_force | O17: 5 | P17: 1 | Q17: 0 | R17: 0 | S17: 0 | T17: 0 | U17: 1 | V17: 0 | W17: 1 | X17: 1 | Y17: 1
... A51: 46255.565 | B51: Kingudam767 | C51: Home | D51: Away | E51: Away | F51: Away | G51: Home | H51: Away | I51: Home | J51: Home | K51: Away | L51: Away | N51: Kingudam767 | O51: 4 | P51: 1 | Q51: 0 | R51: 0 | S51: 0 | T51: 0 | U51: 0 | V51: 1 | W51: 1 | X51: 0 | Y51: 1
A52: 46255.734 | B52: Mangoloid- | D52: Away | E52: Home | F52: Away | G52: Draw | H52: Draw | I52: Away | J52: Draw | K52: Home | L52: Away | N52: Mangoloid- | O52: 2 | P52: 0 | Q52: 0 | R52: 1 | S52: 0 | T52: 0 | U52: 0 | V52: 0 | W52: 0 | X52: 0 | Y52: 1
A53: 46256.16 | B53: Assyoghurt | D53: Away | E53: Draw | F53: Away | G53: Away | H53: Away | I53: Draw | J53: Home | K53: Away | L53: Away | N53: Assyoghurt | O53: 3 | P53: 0 | Q53: 0 | R53: 0 | S53: 0 | T53: 1 | U53: 0 | V53: 0 | W53: 1 | X53: 0 | Y53: 1
A54: 46256.337 | B54: ExCroGamer | E54: Draw | F54: Away | G54: Draw | H54: Away | I54: Draw | J54: Home | K54: Away | L54: Away | N54: ExCroGamer | O54: 2 | P54: 0 | Q54: 0 | R54: 0 | S54: 0 | T54: 0 | U54: 0 | V54: 0 | W54: 1 | X54: 0 | Y54: 1
A55: 46257.069 | B55: DCDA192 | I55: Away | J55: Home | K55: Away | L55: Away | N55: DCDA192 | O55: 2 | P55: 0 | Q55: 0 | R55: 0 | S55: 0 | T55: 0 | U55: 0 | V55: 0 | W55: 1 | X55: 0 | Y55: 1
A56: 46257.335 | B56: Averagefrogenjoyer49 | I56: Away | J56: Home | K56: Away | L56: Away | N56: Averagefrogenjoyer49 | O56: 2 | P56: 0 | Q56: 0 | R56: 0 | S56: 0 | T56: 0 | U56: 0 | V56: 0 | W56: 1 | X56: 0 | Y56: 1
A57: 46259.441 | B57: dahi-hater12 | C57: Home | D57: Away | E57: Away | F57: Away | G57: Home | H57: Home | I57: Home | J57: Away | K57: Home | L57: Home | N57: dahi-hater12 | O57: 9 | P57: 1 | Q57: 1 | R57: 1 | S57: 1 | T57: 0 | U57: 1 | V57: 1 | W57: 1 | X57: 1 | Y57: 1 | AA57: LC R2 | AB57: Ipswich 3 - 1 Leicester | AC57: Plymouth 2 - 4 Coventry | AD57: Stoke 1 (4) - 1 (5) Hull | AE57: Birmingham 1 - 6 Brentford | AF57: Nott'm Forest 0 - 2 Leeds | AG57: Newcastle 3 - 2 West Brom | AH57: Spurs 5 - 1 Charlton | AI57: Preston 0 - 4 Everton | AJ57: Chelsea 2 - 0 Luton | AK57: Fulham 3 - 0 Wimbledon
A58: 46259.441 | B58: JeremysJacquet | C58: Home | D58: Away | E58: Away | F58: Away | G58: Away | H58: Home | I58: Home | J58: Away | K58: Home | L58: Home | N58: JeremysJacquet | O58: 10 | P58: 1 | Q58: 1 | R58: 1 | S58: 1 | T58: 1 | U58: 1 | V58: 1 | W58: 1 | X58: 1 | Y58: 1 | AA58: H | AB58: 24 | AC58: 2 | AD58: 6 | AE58: 3 | AF58: 15 | AG58: 44 | AH58: 42 | AI58: 1 | AJ58: 47 | AK58: 47
A59: 46259.442 | B59: Ummagumma- | C59: Home | D59: Away | E59: Away | F59: Away | G59: Home | H59: Home | I59: Home | J59: Away | K59: Home | L59: Home | N59: Ummagumma- | O59: 9 | P59: 1 | Q59: 1 | R59: 1 | S59: 1 | T59: 0 | U59: 1 | V59: 1 | W59: 1 | X59: 1 | Y59: 1 | AA59: A | AB59: 1 | AC59: 23 | AD59: 19 | AE59: 23 | AF59: 11 | AG59: 2 | AH59: 4 | AI59: 45 | AJ59: 1 | AK59: 1
A60: 46259.443 | B60: ArrozConPollo08 | C60: Home | D60: Away | E60: Away | F60: Away | G60: Home | H60: Home | I60: Home | J60: Away | K60: Home | L60: Home | N60: ArrozConPollo08 | O60: 9 | P60: 1 | Q60: 1 | R60: 1 | S60: 1 | T60: 0 | U60: 1 | V60: 1 | W60: 1 | X60: 1 | Y60: 1
A61: 46259.446 | B61: Konapleto | C61: Home | D61: Away | E61: Away | F61: Away | G61: Home | H61: Home | I61: Home | J61: Away | K61: Home | L61: Home | N61: Konapleto | O61: 9 | P61: 1 | Q61: 1 | R61: 1 | S61: 1 | T61: 0 | U61: 1 | V61: 1 | W61: 1 | X61: 1 | Y61: 1
A62: 46259.446 | B62: bloodyfeelin | C62: Home | D62: Away | E62: Away | F62: Away | G62: Away | H62: Home | I62: Home | J62: Away | K62: Home | L62: Home | N62: bloodyfeelin | O62: 10 | P62: 1 | Q62: 1 | R62: 1 | S62: 1 | T62: 1 | U62: 1 | V62: 1 | W62: 1 | X62: 1 | Y62: 1
A63: 46259.449 | B63: Pyrolaxian | C63: Home | D63: Away | E63: Away | F63: Away | G63: Home | H63: Home | I63: Home | J63: Away | K63: Home | L63: Home | N63: Pyrolaxian | O63: 9 | P63: 1 | Q63: 1 | R63: 1 | S63: 1 | T63: 0 | U63: 1 | V63: 1 | W63: 1 | X63: 1 | Y63: 1
A64: 46259.45 | B64: f4lcon | C64: Home | D64: Away | E64: Away | F64: Away | G64: Away | H64: Home | I64: Home | J64: Away | K64: Home | L64: Home | N64: f4lcon | O64: 10 | P64: 1 | Q64: 1 | R64: 1 | S64: 1 | T64: 1 | U64: 1 | V64: 1 | W64: 1 | X64: 1 | Y64: 1
A65: 46259.453 | B65: AngryScotty22 | C65: Home | D65: Away | E65: Away | F65: Away | G65: Home | H65: Home | I65: Home | J65: Away | K65: Home | L65: Home | N65: AngryScotty22 | O65: 9 | P65: 1 | Q65: 1 | R65: 1 | S65: 1 | T65: 0 | U65: 1 | V65: 1 | W65: 1 | X65: 1 | Y65: 1
A66: 46259.458 | B66: nordic_marksman | C66: Home | D66: Away | E66: Home | F66: Home | G66: Away | H66: Home | I66: Home | J66: Away | K66: Home | L66: Home | N66: nordic_marksman | O66: 8 | P66: 1 | Q66: 1 | R66: 0 | S66: 0 | T66: 1 | U66: 1 | V66: 1 | W66: 1 | X66: 1 | Y66: 1
A67: 46259.459 | B67: RandomGuySayHii | C67: Home | D67: Away | E67: Away | F67: Away | G67: Home | H67: Home | I67: Home | J67: Away | K67: Home | L67: Home | N67: RandomGuySayHii | O67: 9 | P67: 1 | Q67: 1 | R67: 1 | S67: 1 | T67: 0 | U67: 1 | V67: 1 | W67: 1 | X67: 1 | Y67: 1
A68: 46259.474 | B68: loveandmonsters | C68: Home | D68: Away | E68: Away | F68: Away | G68: Home | H68: Home | I68: Home | J68: Away | K68: Home | L68: Home | N68: loveandmonsters | O68: 9 | P68: 1 | Q68: 1 | R68: 1 | S68: 1 | T68: 0 | U68: 1 | V68: 1 | W68: 1 | X68: 1 | Y68: 1
A69: 46259.475 | B69: IisIgnorantAF | C69: Home | D69: Away | E69: Away | F69: Away | G69: Home | H69: Home | I69: Home | J69: Away | K69: Home | L69: Home | N69: IisIgnorantAF | O69: 9 | P69: 1 | Q69: 1 | R69: 1 | S69: 1 | T69: 0 | U69: 1 | V69: 1 | W69: 1 | X69: 1 | Y69: 1
A70: 46259.487 | B70: Art_schlock | C70: Home | D70: Away | E70: Away | F70: Away | G70: Home | H70: Home | I70: Home | J70: Away | K70: Home | L70: Home | N70: Art_schlock | O70: 9 | P70: 1 | Q70: 1 | R70: 1 | S70: 1 | T70: 0 | U70: 1 | V70: 1 | W70: 1 | X70: 1 | Y70: 1
A71: 46259.489 | B71: MadeMIGMIG | C71: Home | D71: Away | E71: Away | F71: Away | G71: Home | H71: Home | I71: Home | J71: Away | K71: Home | L71: Home | N71: MadeMIGMIG | O71: 9 | P71: 1 | Q71: 1 | R71: 1 | S71: 1 | T71: 0 | U71: 1 | V71: 1 | W71: 1 | X71: 1 | Y71: 1
... A81: 46259.614 | B81: ASGT908 | C81: Home | D81: Away | E81: Home | F81: Home | G81: Away | H81: Home | I81: Home | J81: Home | K81: Home | L81: Home | N81: ASGT908 | O81: 7 | P81: 1 | Q81: 1 | R81: 0 | S81: 0 | T81: 1 | U81: 1 | V81: 1 | W81: 0 | X81: 1 | Y81: 1
A82: 46259.624 | B82: MatSa_ | F82: Away | G82: Home | H82: Home | I82: Home | J82: Away | K82: Home | L82: Home | N82: MatSa_ | O82: 6 | P82: 0 | Q82: 0 | R82: 0 | S82: 1 | T82: 0 | U82: 1 | V82: 1 | W82: 1 | X82: 1 | Y82: 1
...

Sheet Sheet1
A1: * Round 1 (PL MD1) | D1: * Round 2 (LC R2) | G1: * Round 3 (PL MD2) | J1: * Round 4 (PL MD3) | M1: * Round 5 (UCL MD1) | P1: * Round 6 (PL MD4)
A2: {=sort('Form Responses 1'!N2:O56,'Form Responses 1'!O2:O56,0)} -> zigooloo | B2: 6 | D2: {=sort('Form Responses 1'!N57:O104,'Form Responses 1'!O57:O104,0)} -> JeremysJacquet | E2: 10 | G2: {=sort('Form Responses 1'!N105:O134,'Form Responses 1'!O105:O134,0)} -> HuskyFeline0927 | H2: 7 | J2: {=sort('Form Responses 1'!N135:O174,'Form Responses 1'!O135:O174,0)} -> WaifuWarrior18 | K2: 7 | M2: {=sort('Form Responses 1'!N175:O212,'Form Responses 1'!O175:O212,0)} -> loveandmonsters | N2: 10 | P2: {=sort('Form Responses 1'!N213:O245,'Form Responses 1'!O213:O245,0)} -> mchto | Q2: 6 | R2: =P19 -> KickStanKick | S2: =Q19 -> 3
A3: AndyB_1010 | B3: 6 | D3: bloodyfeelin | E3: 10 | G3: asparagusdreaming | H3: 7 | J3: none | K3: 7 | M3: qqq666 | N3: 10 | P3: Wtfitsd | Q3: 6 | R3: =P20 -> Sylviek | S3: =Q20 -> 3
A4: sockodile | B4: 6 | D4: f4lcon | E4: 10 | G4: afternoonshat | H4: 6 | J4: TheLoudAss | K4: 6 | M4: IkkeLilje | N4: 10 | P4: Alet404 | Q4: 6 | R4: =P21 -> Bosscher47 | S4: =Q21 -> 3
A5: mantj23 | B5: 6 | D5: crepss | E5: 10 | G5: Ignatius_Reillys_Hat | H5: 6 | J5: AngryScotty22 | K5: 6 | M5: Mrchestofdrawers | N5: 9 | P5: HuskyFeline0927 | Q5: 5 | R5: =P22 -> Rithvikstar123 | S5: =Q22 -> 3
A6: 26ld | B6: 5 | D6: Medaculous | E6: 10 | G6: Ponzales | H6: 6 | J6: kopite33 | K6: 6 | M6: f4lcon | N6: 9 | P6: agntkay | Q6: 5 | R6: =P23 -> CB5 | S6: =Q23 -> 3
A7: JhnCook | B7: 5 | D7: dahi-hater12 | E7: 9 | G7: ross_a_m | H7: 6 | J7: Joopface | K7: 6 | M7: KickStanKick | N7: 9 | P7: AngryScotty22 | Q7: 5 | R7: =P24 -> Thaisis | S7: =Q24 -> 3
A8: mystic_wang_force | B8: 5 | D8: Ummagumma- | E8: 9 | G8: Shoumaker | H8: 6 | J8: mchto | K8: 6 | M8: ASGT908 | N8: 9 | P8: loveandmonsters | Q8: 5 | R8: =P25 -> Hawkeye5481 | S8: =Q25 -> 3
A9: Noisogard | B9: 5 | D9: ArrozConPollo08 | E9: 9 | G9: Babyfaceknees | H9: 6 | J9: SpiritedBed2305 | K9: 6 | M9: TraceOfHumanity | N9: 9 | P9: ExCroGamer | Q9: 5 | R9: =P26 -> Neildrill | S9: =Q26 -> 3
A10: mirest | B10: 5 | D10: Konapleto | E10: 9 | G10: iamm4r4 | H10: 5 | J10: pagansaints | K10: 6 | M10: sockodile | N10: 9 | P10: No-Comfortable5902 | Q10: 5 | R10: =P27 -> nordic_marksman | S10: =Q27 -> 3
A11: Everybodylies7 | B11: 5 | D11: Pyrolaxian | E11: 9 | G11: MadeMIGMIG | H11: 5 | J11: mantj23 | K11: 6 | M11: Rithvikstar123 | N11: 9 | P11: JeremysJacquet | Q11: 4 | R11: =P28 -> blabla12356 | S11: =Q28 -> 3
A12: Smalk | B12: 5 | D12: AngryScotty22 | E12: 9 | G12: ttcolector | H12: 5 | J12: narwoolTF2 | K12: 5 | M12: iroh027 | N12: 9 | P12: f4lcon | Q12: 4 | R12: =P29 -> Ignatius_Reillys_Hat | S12: =Q29 -> 3
A13: Surreptitiousnoun | B13: 5 | D13: RandomGuySayHii | E13: 9 | G13: Wafflebreeder | H13: 5 | J13: Alet404 | K13: 5 | M13: TB_barky | N13: 9 | P13: Urumeesthambaan | Q13: 4 | R13: =P30 -> ASGT908 | S13: =Q30 -> 2
A14: m_audette99 | B14: 4 | D14: loveandmonsters | E14: 9 | G14: Ninovd | H14: 5 | J14: Neildrill | K14: 5 | M14: nordic_marksman | N14: 9 | P14: b112b112b | Q14: 4 | R14: =P31 -> yobroyobro | S14: =Q31 -> 2
... A17: narwoolTF2 | B17: 4 | D17: MadeMIGMIG | E17: 9 | G17: DefinitelyNotBarney | H17: 4 | J17: blackjack47 | K17: 5 | M17: Alet404 | N17: 8 | P17: narwoolTF2 | Q17: 3 | R17: =P34 -> djnole | S17: =Q34 -> 2
A18: Uuu | B18: 4 | D18: No-Syrup8581 | E18: 9 | G18: JeremysJacquet | H18: 4 | J18: ASGT908 | K18: 5 | M18: Lanky_Comment_6452 | N18: 8 | P18: FireyFan230 | Q18: 3
A19: Downtown-Peach-2326 | B19: 4 | D19: Janus93r | E19: 9 | G19: CB5 | H19: 4 | J19: b112b112b | K19: 5 | M19: b112b112b | N19: 8 | P19: KickStanKick | Q19: 3
A20: Gremlin2471 | B20: 4 | D20: Koplade | E20: 9 | G20: bosscher47 | H20: 4 | J20: Ignatius_Reillys_Hat | K20: 5 | M20: RandomGuySayHii | N20: 8 | P20: Sylviek | Q20: 3
A21: Pyrolaxian | B21: 4 | D21: nordic_marksman | E21: 8 | G21: mirest | H21: 4 | J21: sockodile | K21: 5 | M21: b_k_l_y | N21: 8 | P21: Bosscher47 | Q21: 3
A22: f4lcon | B22: 4 | D22: DragonSpawn | E22: 8 | G22: f4lcon | H22: 4 | J22: -Mangoloid | K22: 5 | M22: Anonymous | N22: 8 | P22: Rithvikstar123 | Q22: 3
A23: Alet404 | B23: 4 | D23: metalelf0 | E23: 8 | G23: Ummagumma- | H23: 4 | J23: TraceOfHumanity | K23: 5 | M23: Furu97 | N23: 8 | P23: CB5 | Q23: 3
A24: Jakebrickley | B24: 4 | D24: zigooloo | E24: 8 | G24: Sockodile | H24: 4 | J24: FreddieWhey | K24: 4 | M24: Ignatius_Reillys_Hat | N24: 8 | P24: Thaisis | Q24: 3
A25: glass_oni0n | B25: 4 | D25: sockodile | E25: 7 | G25: DragonSpawn | H25: 3 | J25: loveandmonsters | K25: 4 | M25: Kopite33 | N25: 8 | P25: Hawkeye5481 | Q25: 3
A26: Sonion | B26: 4 | D26: ASGT908 | E26: 7 | G26: yobroyobro | H26: 3 | J26: DefinitelyNotBarney | K26: 4 | M26: AngryScotty22 | N26: 8 | P26: Neildrill | Q26: 3
A27: NoSalahNoParty | B27: 4 | D27: MatSa_ | E27: 6 | G27: Apprehensive_Leg5209 | H27: 3 | J27: Qqq666 | K27: 4 | M27: Ninovd | N27: 8 | P27: nordic_marksman | Q27: 3
A28: Kingudam767 | B28: 4 | D28: WaifuWarrior18 | E28: 5 | G28: TraceOfHumanity | H28: 3 | J28: aeceus | K28: 4 | M28: zigooloo | N28: 8 | P28: blabla12356 | Q28: 3
A29: MadeMIGMIG | B29: 3 | D29: That_welsh_guy | E29: 5 | G29: Alet404 | H29: 2 | J29: MachineSuccesful175 | K29: 4 | M29: skycloudfanfic | N29: 8 | P29: Ignatius_Reillys_Hat | Q29: 3
... A31: Ummagumma- | B31: 3 | D31: TraceOfHumanity | E31: 5 | G31: b112b112b | H31: 1 | J31: Wafflebreeder | K31: 4 | M31: WaifuWarrior18 | N31: 7 | P31: yobroyobro | Q31: 2
A32: Dudhjalebi | B32: 3 | D32: zzupler | E32: 5 | J32: ExCroGamer | K32: 4 | M32: 128palms | N32: 7 | P32: zigooloo | Q32: 2
A33: Ninovd | B33: 3 | D33: JeremyJ | E33: 5 | J33: No-Comfortable5902 | K33: 4 | M33: Neildrill | N33: 7 | P33: Shoumaker | Q33: 2
A34: ASGT908 | B34: 3 | D34: Jack__Beanz | E34: 5 | J34: b_k_l_y | K34: 4 | M34: aeceus | N34: 7 | P34: djnole | Q34: 2
A35: loveandmonsters | B35: 3 | D35: MrCCCraft | E35: 5 | J35: nordic_marksman | K35: 3 | M35: UniversalStall0ne | N35: 7
A36: nunyaXS | B36: 3 | D36: Allstar3553 | E36: 5 | J36: zigooloo | K36: 3 | M36: narwoolTF2 | N36: 7
A37: AngryScotty22 | B37: 3 | D37: skycloudfanfic | E37: 5 | J37: McyNmiFT | K37: 3 | M37: Shoumaker | N37: 6
A38: Ignatius_Reillys_Hat | B38: 3 | D38: Informal_Nobody_7020 | E38: 5 | J38: Rithvikstar123 | K38: 3 | M38: MadeMIGMIG | N38: 5
A39: Informal_Nobody_7020 | B39: 3 | D39: Cactuar1989 | E39: 5 | J39: MadeMIGMIG | K39: 3 | M39: ExCroGamer | N39: 4
A40: LFC908 | B40: 3 | D40: mantj23 | E40: 5 | J40: Ninovd | K40: 3
A41: SerialExperimentLean | B41: 3 | D41: Anuj_agarwal_78 | E41: 5 | J41: CB5 | K41: 1
A42: clasicgap529 | B42: 3 | D42: J_Stargazer | E42: 5
A43: BreakingShermorty | B43: 3 | D43: Cl414 | E43: 4
...

Sheet Sheet2
A1: {=sort('Form Responses 1'!N2:O212,'Form Responses 1'!N2:N212,1)} -> -Mangoloid | B1: 5 | D1: =A1 -> -Mangoloid | E1: =B1 -> 5 | M1: {=sort(D1:E1000,E1:E1000,0)} -> bloodyfeelin | N1: 10
A2: 128palms | B2: 7 | D2: =IF(A2=A1,"",A2) -> 128palms | E2: =B2 -> 7 | M2: crepss | N2: 10
A3: 26ld | B3: 5 | D3: =IF(A3=A2,"",A3) -> 26ld | E3: =B3 -> 5 | N3: 10
A4: aeceus | B4: 4 | D4: =IF(A4=A3,"",A4) -> aeceus | E4: =B4 -> 4 | M4: IkkeLilje | N4: 10
A5: aeceus | B5: 7 | D5: =IF(A5=A4,"",A5) | E5: =B5 -> 7 | M5: JeremysJacquet | N5: 10
A6: AffectionateLeg9895 | B6: 3 | D6: =IF(A6=A5,"",A6) -> AffectionateLeg9895 | E6: =B6 -> 3 | N6: 10
A7: afternoonshat | B7: 6 | D7: =IF(A7=A6,"",A7) -> afternoonshat | E7: =B7 -> 6 | M7: Medaculous | N7: 10
A8: Alet404 | B8: 4 | D8: =IF(A8=A7,"",A8) -> Alet404 | E8: =B8 -> 4 | N8: 10
A9: Alet404 | B9: 2 | D9: =IF(A9=A8,"",A9) | E9: =B9 -> 2 | N9: 9
A10: Alet404 | B10: 2 | D10: =IF(A10=A9,"",A10) | E10: =B10 -> 2 | M10: ArrozConPollo08 | N10: 9
A11: Alet404 | B11: 5 | D11: =IF(A11=A10,"",A11) | E11: =B11 -> 5 | M11: Art_schlock | N11: 9
A12: Alet404 | B12: 8 | D12: =IF(A12=A11,"",A12) | E12: =B12 -> 8 | N12: 9
A13: Allstar3553 | B13: 5 | D13: =IF(A13=A12,"",A13) -> Allstar3553 | E13: =B13 -> 5 | M13: dahi-hater12 | N13: 9
A14: AndyB_1010 | B14: 6 | D14: =IF(A14=A13,"",A14) -> AndyB_1010 | E14: =B14 -> 6 | N14: 9
A15: AngryScotty22 | B15: 3 | D15: =IF(A15=A14,"",A15) -> AngryScotty22 | E15: =B15 -> 3 | M15: IisIgnorantAF | N15: 9
A16: AngryScotty22 | B16: 9 | D16: =IF(A16=A15,"",A16) | E16: =B16 -> 9 | M16: iroh027 | N16: 9
A17: AngryScotty22 | B17: 6 | D17: =IF(A17=A16,"",A17) | E17: =B17 -> 6 | M17: Janus93r | N17: 9
A18: AngryScotty22 | B18: 8 | D18: =IF(A18=A17,"",A18) -> AngryScotty22 | E18: =B18 -> 8 | M18: KickStanKick | N18: 9
A19: Anonymous | B19: 8 | D19: =IF(A19=A18,"",A19) -> Anonymous | E19: =B19 -> 8 | M19: Konapleto | N19: 9
A20: Anuj_agarwal_78 | B20: 5 | D20: =IF(A20=A19,"",A20) -> Anuj_agarwal_78 | E20: =B20 -> 5 | M20: Koplade | N20: 9
A21: Apprehensive_Leg5209 | B21: 3 | D21: =IF(A21=A20,"",A21) -> Apprehensive_Leg5209 | E21: =B21 -> 3 | M21: Loud_Jellyfish_6267 | N21: 9
A22: ArrozConPollo08 | B22: 9 | D22: =IF(A22=A21,"",A22) -> ArrozConPollo08 | E22: =B22 -> 9 | N22: 9
A23: Art_schlock | B23: 9 | D23: =IF(A23=A22,"",A23) -> Art_schlock | E23: =B23 -> 9 | N23: 9
A24: ASGT908 | B24: 3 | D24: =IF(A24=A23,"",A24) -> ASGT908 | E24: =B24 -> 3 | M24: Mrchestofdrawers | N24: 9
A25: ASGT908 | B25: 7 | D25: =IF(A25=A24,"",A25) | E25: =B25 -> 7 | M25: No-Syrup8581 | N25: 9
A26: ASGT908 | B26: 5 | D26: =IF(A26=A25,"",A26) | E26: =B26 -> 5 | N26: 9
A27: ASGT908 | B27: 9 | D27: =IF(A27=A26,"",A27) | E27: =B27 -> 9 | N27: 9
A28: asparagusdreaming | B28: 2 | D28: =IF(A28=A27,"",A28) -> asparagusdreaming | E28: =B28 -> 2 | M28: RandomGuySayHii | N28: 9
A29: asparagusdreaming | B29: 7 | D29: =IF(A29=A28,"",A29) | E29: =B29 -> 7 | N29: 9
A30: Assyoghurt | B30: 3 | D30: =IF(A30=A29,"",A30) -> Assyoghurt | E30: =B30 -> 3 | N30: 9
A31: Averagefrogenjoyer49 | B31: 2 | D31: =IF(A31=A30,"",A31) -> Averagefrogenjoyer49 | E31: =B31 -> 2 | M31: TB_barky | N31: 9
A32: b_k_l_y | B32: 4 | D32: =IF(A32=A31,"",A32) -> b_k_l_y | E32: =B32 -> 4 | N32: 9
A33: b_k_l_y | B33: 8 | D33: =IF(A33=A32,"",A33) | E33: =B33 -> 8 | N33: 9
A34: b112b112b | B34: 1 | D34: =IF(A34=A33,"",A34) -> b112b112b | E34: =B34 -> 1 | N34: 9
A35: b112b112b | B35: 5 | D35: =IF(A35=A34,"",A35) | E35: =B35 -> 5 | N35: 8
A36: b112b112b | B36: 8 | D36: =IF(A36=A35,"",A36) | E36: =B36 -> 8 | M36: AngryScotty22 | N36: 8
A37: Babyfaceknees | B37: 6 | D37: =IF(A37=A36,"",A37) -> Babyfaceknees | E37: =B37 -> 6 | M37: Anonymous | N37: 8
A38: blackjack47 | B38: 5 | D38: =IF(A38=A37,"",A38) -> blackjack47 | E38: =B38 -> 5 | N38: 8
A39: bloodyfeelin | B39: 10 | D39: =IF(A39=A38,"",A39) -> bloodyfeelin | E39: =B39 -> 10 | N39: 8
A40: bosscher47 | B40: 4 | D40: =IF(A40=A39,"",A40) -> bosscher47 | E40: =B40 -> 4 | N40: 8
...
